<?xml version='1.0'?>

<robot name="my_robot" xmlns:xacro="http://www.ros.org/wiki/xacro">

<xacro:include filename="$(find my_robot)/urdf/my_robot.gazebo" />

  <link name="robot_footprint"></link>

  <joint name="robot_footprint_joint" type="fixed">
    <origin xyz="0 0 0" rpy="0 0 0" />
    <parent link="robot_footprint"/>
    <child link="chassis" />
  </joint>

  <link name='chassis'>
    <pose>0 0 0.1 0 0 0</pose>

    <inertial>
      <mass value="10"/>
      <origin xyz="0.0 0 0" rpy=" 0 0 0"/>
      <inertia
          ixx="0.08" ixy="0" ixz="0"
          iyy="0.08" iyz="0"
          izz="0.15"
      />
    </inertial>

    <collision name='collision'>
      <origin xyz="0 0 0" rpy=" 0 0 0"/> 
      <geometry>
        <box size=".15 .1 .04"/>
      </geometry>
    </collision>

    <visual name='chassis_visual'>
      <origin xyz="0 0 0" rpy=" 0 0 0"/>
      <geometry>
        <box size=".15 .1 .04"/>
      </geometry>
    </visual>


    <collision name='back_caster_collision'>
      <origin xyz="-0.07 0 -0.020" rpy=" 0 0 0"/>
      <geometry>
        <sphere radius="0.01"/>
      </geometry>
    </collision>

    <visual name='back_caster_visual'>
      <origin xyz="-0.07 0 -0.020" rpy=" 0 0 0"/>
      <geometry>
        <sphere radius="0.01"/>
      </geometry>
    </visual>

    <collision name='front_caster_collision'>
      <origin xyz="0.07 0 -0.020" rpy=" 0 0 0"/>
      <geometry>
        <sphere radius="0.01"/>
      </geometry>
    </collision>

    <visual name='front_caster_visual'>
      <origin xyz="0.07 0 -0.020" rpy=" 0 0 0"/>
      <geometry>
        <sphere radius="0.01"/>
      </geometry>
    </visual>

  </link>
  
    <gazebo reference="left_wheel">
    <material>Gazebo/White</material>
    </gazebo>
    
    <gazebo reference="right_wheel">
    <material>Gazebo/White</material>
    </gazebo>
    
    <gazebo reference="chassis">
    <material>Gazebo/Green</material>
    </gazebo>
    
    <gazebo reference="camera">
    <material>Gazebo/Black</material>
    </gazebo>
    
    <link name="hokuyo">
    <pose> 0 0 0 0 0 0</pose>
    
     <inertial>
      <mass value="1e-5"/>
      <origin xyz="0 0 0" rpy=" 0 0 0"/>
      <inertia
          ixx="1e-6" ixy="0" ixz="0"
          iyy="1e-6" iyz="0"
          izz="1e-6"
      />
    </inertial>

    <collision name='collision'>
      <origin xyz="0 0 0" rpy=" 0 0 0"/>
      <geometry>
         <box size="0.1 0.1 0.1"/>
      </geometry>
    </collision>

    <visual name='visual'>
    <origin xyz="0 0 0" rpy=" 0 0 0"/>
    <geometry>
    <mesh filename="package://my_robot/meshes/hokuyo.dae"/>
    </geometry>
    </visual>
    
    </link>
    
    <joint type="fixed" name="hokuyo_joint">
    <origin xyz="0 0 0.025" rpy="0 0 0" />
    <child link="hokuyo"/>
    <parent link="chassis"/>
    <axis xyz="0 1 0" rpy="0 0 0"/>
    </joint>

   <link name="camera">
   <pose> 0 0 0 0 0 0</pose>

    <inertial>
      <mass value="1e-5"/>
      <origin xyz="0 0 0" rpy=" 0 0 0"/>
      <inertia
          ixx="1e-6" ixy="0" ixz="0"
          iyy="1e-6" iyz="0"
          izz="1e-6"
      />
      <box_inertia m="0.1" x="0.05" y="0.05" z="0.05"/>
    </inertial>

    <collision name='collision'>
      <origin xyz="0 0 0" rpy=" 0 0 0"/>
      <geometry>
         <box size="0.025 0.025 0.025"/>
      </geometry>
    </collision>

    <visual name='visual'>
      <origin xyz="0 0 0" rpy=" 0 0 0"/>
      <geometry>
        <box size="0.025 0.025 0.025"/>
      </geometry>
    </visual>
   </link>
   
   <joint type="fixed" name="camera_joint">
    <origin xyz="0.075 0 0.0325" rpy="0 0 0" />
    <child link="camera"/>
    <parent link="chassis"/>
    <axis xyz="0 1 0" rpy="0 0 0"/>
    </joint>

    <link name="left_wheel">
    <pose>0 0 0 0 0 0</pose>

    <inertial>
      <mass value="1.5"/>
      <origin xyz="0 0 0" rpy=" 0 1.5707 1.5707"/>
      <inertia
          ixx="0.01" ixy="0" ixz="0"
          iyy="0.01" iyz="0"
          izz="0.01"
      />
    </inertial>

    <collision name='collision'>
      <origin xyz="0 0 0" rpy=" 0 1.5707 1.5707"/>
      <geometry>
         <cylinder length="0.015" radius="0.03"/>
      </geometry>
    </collision>

    <visual name='visual'>
      <origin xyz="0 0 0" rpy=" 0 1.5707 1.5707"/>
      <geometry>
        <cylinder length="0.015" radius="0.03"/>
      </geometry>
    </visual>
    </link>
    
    <link name="right_wheel">
    <pose>0 0 0 0 0 0</pose>

    <inertial>
      <mass value="1.5"/>
      <origin xyz="0 0 0" rpy=" 0 1.5707 1.5707"/>
      <inertia
          ixx="0.01" ixy="0" ixz="0"
          iyy="0.01" iyz="0"
          izz="0.01"
      />
    </inertial>

    <collision name='collision'>
      <origin xyz="0 0 0" rpy=" 0 1.5707 1.5707"/>
      <geometry>
         <cylinder length="0.015" radius="0.03"/>
      </geometry>
    </collision>

    <visual name='visual'>
      <origin xyz="0 0 0" rpy=" 0 1.5707 1.5707"/>
      <geometry>
         <cylinder length="0.015" radius="0.03"/>
      </geometry>
    </visual>
    </link>
    
   <joint type="continuous" name="left_wheel_hinge">
    <origin xyz="0 0.06 0" rpy="0 0 0" />
    <child link="left_wheel"/>
    <parent link="chassis"/>
    <axis xyz="0 1 0" rpy="0 0 0"/>
    <limit effort="10000" velocity="2000"/>
    <dynamics damping="1.0" friction="1.0"/>
    </joint>
    
    <joint type="continuous" name="right_wheel_hinge">
    <origin xyz="0 -0.06 0" rpy="0 0 0" />
    <child link="right_wheel"/>
    <parent link="chassis"/>
    <axis xyz="0 1 0" rpy="0 0 0"/>
    <limit effort="10000" velocity="2000"/>
    <dynamics damping="1.0" friction="1.0"/>
    </joint>

</robot>
